Workbook

Sheet Lead Tracker
A1: ECOMMERCE CLIENT LEAD TRACKER – 250 Prospects
A2: All leads are UNCONTACTED — Start outreach from top. Use Status dropdown to track progress.
A3: # | B3: Business Name | C3: Owner / Contact Name | D3: Business Type | E3: City | F3: Phone Number | G3: Email Address | H3: Instagram / FB | I3: Website | J3: Lead Source | K3: Status | L3: Follow-up Date | M3: Priority | N3: Est. Deal Value (₹) | O3: Notes
A4: 1 | B4: Prime Motors | C4: Vivek Shah | D4: Auto Parts | E4: Gandhinagar | F4: +91 97270 18196 | G4: vivek.shah@gmail.com | H4: None | I4: None | J4: Google Maps | K4: Not Contacted | M4: Medium
A5: 2 | B5: Sai Art | C5: Neha Verma | D5: Gifts / Handmade | E5: Morbi | F5: +91 99110 63794 | G5: neha.verma@yahoo.com | H5: @sai_art | I5: None | J5: WhatsApp Group | K5: Not Contacted | M5: Medium
A6: 3 | B6: Star Pets | C6: Hetal Trivedi | D6: Pet Supplies | E6: Anand | F6: +91 92660 15594 | G6: hetal.trivedi@outlook.com | H6: @star_pets | I6: None | J6: Trade Fair | K6: Not Contacted | M6: High
A7: 4 | B7: City Athletics | C7: Naresh Dave | D7: Sports / Fitness | E7: Jamnagar | F7: +91 96560 31034 | G7: naresh.dave123@yahoo.com | H7: @city_athletics | I7: None | J7: Trade Fair | K7: Not Contacted | M7: Medium
A8: 5 | B8: Urban Gold | C8: Sneha Agrawal | D8: Jewellery | E8: Vadodara | F8: +91 90160 41928 | G8: sneha.agrawal99@yahoo.com | H8: @urban_gold | I8: None | J8: LinkedIn | K8: Not Contacted | M8: Low
A9: 6 | B9: Balaji Dairy | C9: Ashok Soni | D9: Dairy / Subscription | E9: Amreli | F9: +91 91060 05641 | G9: ashok.soni99@rediffmail.com | H9: @balaji_dairy | I9: None | J9: WhatsApp Group | K9: Not Contacted | M9: High
A10: 7 | B10: Classic Athletics | C10: Rohan Iyer | D10: Sports / Fitness | E10: Bharuch | F10: +91 97270 38849 | G10: rohan.iyer_co@rediffmail.com | H10: @classic_athletics | I10: None | J10: Google Maps | K10: Not Contacted | M10: High
A11: 8 | B11: Mera Pets | C11: Rohan Modi | D11: Pet Supplies | E11: Ahmedabad | F11: +91 97270 26916 | G11: rohan.modi_co@rediffmail.com | H11: @mera_pets | I11: None | J11: Cold Email | K11: Not Contacted | M11: Medium
A12: 9 | B12: Om Automobiles | C12: Priya Soni | D12: Auto Parts | E12: Surat | F12: +91 77980 45146 | G12: priya.soni_biz@outlook.com | H12: None | I12: None | J12: LinkedIn | K12: Not Contacted | M12: Medium
A13: 10 | B13: Sai Namkeen | C13: Manish Gupta | D13: Food / FMCG | E13: Amreli | F13: +91 63590 89325 | G13: manish.gupta_biz@rediffmail.com | H13: @sai_namkeen | I13: None | J13: Cold Email | K13: Not Contacted | M13: High
A14: 11 | B14: Town Boutique | C14: Paresh Sharma | D14: Clothing / Fashion | E14: Surat | F14: +91 74050 43039 | G14: paresh.sharma123@gmail.com | H14: @town_boutique | I14: None | J14: JustDial | K14: Not Contacted | M14: Medium
A15: 12 | B15: Top Decor | C15: Haresh Joshi | D15: Furniture / Home Decor | E15: Bharuch | F15: +91 93270 89638 | G15: haresh.joshi99@hotmail.com | H15: @top_decor | I15: None | J15: WhatsApp Group | K15: Not Contacted | M15: Medium
... A253: 250 | B253: Dinesh Glow | C253: Dinesh Nair | D253: Beauty / Skincare | E253: Amreli | F253: +91 93270 37489 | G253: dinesh.nair_co@rediffmail.com | H253: None | I253: None | J253: Cold Email | K253: Not Contacted | M253: Low

Sheet Pricing & Packages
A1: PRICING STRATEGY & BUSINESS MODEL — Ecommerce Website Services
A3: 📦 SERVICE PACKAGES — What to Charge
A4: # | B4: Package | C4: Best For | D4: Key Features | E4: Setup (₹) | F4: AMC/yr (₹) | G4: Monthly SaaS (₹) | H4: Delivery | I4: Notes
A5: 1 | B5: Quick Launch | C5: Home sellers, first-timers | D5: Template store, 3 pages, 20 products, UPI+COD | E5: 8,000 | F5: 3,000 | G5: 900 | H5: 3–5 days
A6: 2 | B6: Starter Store | C6: Small retailers, food, crafts | D6: 5 pages, 50 products, UPI+COD, WhatsApp chat | E6: 15,000 | F6: 6,000 | G6: 1,500 | H6: 7–10 days
A7: 3 | B7: Growth Store | C7: Clothing, food, gifting | D7: 10 pages, 200 products, coupons, reviews, basic analytics | E7: 30,000 | F7: 10,000 | G7: 2,500 | H7: 14–18 days
A8: 4 | B8: Pro Store | C8: Electronics, hardware, medical | D8: Unlimited products, inventory, order mgmt, Razorpay, analytics | E8: 55,000 | F8: 18,000 | G8: 4,500 | H8: 21–28 days
A9: 5 | B9: Enterprise | C9: Manufacturer, D2C brand, B2B | D9: Custom design, ERP/GST integration, multi-vendor, API | E9: 1,20,000 | F9: 35,000 | G9: 8,000 | H9: 45–60 days
A11: 🏗️ BUSINESS MODELS — How to Charge
A12: # | B12: Model | C12: How It Works | D12: Upfront (₹) | E12: Recurring/mo (₹) | F12: Best For | G12: Pro | H12: Con | I12: Verdict
A13: 1 | B13: One-Time + AMC | C13: Pay once for build + annual maintenance | D13: 25k–1.2L | E13: 0 (AMC: 3k–35k/yr) | F13: SMBs, retailers | G13: Predictable revenue | H13: No MRR | I13: Good Start
A14: 2 | B14: SaaS Monthly | C14: Low setup + monthly platform fee | D14: 5k–15k | E14: 1,500–8,000 | F14: Startups, home sellers | G14: Growing MRR | H14: Slow revenue start | I14: Best Long-Term
A15: 3 | B15: Hybrid (Recommended) | C15: Medium setup + ongoing SaaS fee | D15: 15k–45k | E15: 2,000–5,000 | F15: All types | G15: Cash + MRR balance | H15: Needs clear explanation | I15: BEST MODEL ⭐
A16: 4 | B16: Retainer | C16: Fixed monthly for updates + support | D16: 10k–20k | E16: 5,000–15,000 | F16: Growing brands | G16: High sticky MRR | H16: Bandwidth heavy | I16: Add-on to SaaS
A17: 5 | B17: One-Time Only | C17: Single payment, no contract | D17: 15k–80k | E17: 0 | F17: Budget-conscious | G17: Simple close | H17: Feast-or-famine | I17: Avoid alone
A19: 📊 REVENUE PROJECTOR — Estimated Monthly Income
A20: Metric | B20: Mo 1 | C20: Mo 2 | D20: Mo 3 | E20: Mo 6 | F20: Mo 9 | G20: Mo 12 | H20: Year 2 | I20: Year 3
A21: New Clients / Month | B21: 1 | C21: 2 | D21: 3 | E21: 4 | F21: 5 | G21: 6 | H21: 10 | I21: 15
A22: Avg Setup Fee (₹) | B22: 20000 | C22: 22000 | D22: 25000 | E22: 30000 | F22: 32000 | G22: 35000 | H22: 40000 | I22: 45000
A23: One-Time Revenue (₹) | B23: =B22*B21 -> 20000 | C23: =C22*C21 -> 44000 | D23: =D22*D21 -> 75000 | E23: =E22*E21 -> 120000 | F23: =F22*F21 -> 160000 | G23: =G22*G21 -> 210000 | H23: =H22*H21 -> 400000 | I23: =I22*I21 -> 675000
A24: SaaS Clients (Total) | B24: 0 | C24: 1 | D24: 3 | E24: 9 | F24: 16 | G24: 26 | H24: 55 | I24: 95
A25: Avg SaaS Fee/mo (₹) | B25: 2500 | C25: 2500 | D25: 2500 | E25: 3000 | F25: 3000 | G25: 3500 | H25: 3500 | I25: 4000
A26: SaaS Revenue/mo (₹) | B26: =B25*B24 -> 0 | C26: =C25*C24 -> 2500 | D26: =D25*D24 -> 7500 | E26: =E25*E24 -> 27000 | F26: =F25*F24 -> 48000 | G26: =G25*G24 -> 91000 | H26: =H25*H24 -> 192500 | I26: =I25*I24 -> 380000
A27: AMC Revenue/mo (₹) | B27: 0 | C27: 0 | D27: 1000 | E27: 3000 | F27: 6000 | G27: 10000 | H27: 22000 | I27: 40000
A28: TOTAL Revenue/mo (₹) | B28: =B23+B26+B27 -> 20000 | C28: =C23+C26+C27 -> 46500 | D28: =D23+D26+D27 -> 83500 | E28: =E23+E26+E27 -> 150000 | F28: =F23+F26+F27 -> 214000 | G28: =G23+G26+G27 -> 311000 | H28: =H23+H26+H27 -> 614500 | I28: =I23+I26+I27 -> 1095000

Sheet Infrastructure Costs
A1: INFRASTRUCTURE COST CALCULATOR — Per Client Deployment
A2: Stack: Next.js (Frontend) | Supabase (Database + Storage) | Vercel (Hosting) | Razorpay (Payments)
A4: 💸 PER CLIENT — ONE-TIME SETUP COSTS (You Pay)
A5: Item | B5: Provider | C5: Plan | D5: Cost (INR) | E5: Cost (USD) | F5: Frequency | G5: Billable to Client? | H5: Notes
A6: Domain (.in / .com) | B6: GoDaddy / Namecheap | C6: 1 year | D6: 700 – 1,200 | E6: ~$9–14 | F6: Annual | G6: Yes — charge client | H6: Add ₹500 margin. .in ≈ ₹700, .com ≈ ₹1,200
A7: SSL Certificate | B7: Vercel (auto) | C7: Free with Vercel | D7: 0 | E7: $0 | F7: Included | G7: N/A | H7: Let's Encrypt SSL auto-applied on Vercel
A8: Next.js Frontend Hosting | B8: Vercel | C8: Hobby (free) / Pro | D8: 0 – 1,700/mo | E8: $0–$20/mo | F8: Monthly | G8: Included in SaaS fee | H8: Hobby free up to 100GB bandwidth. Pro for team
A9: Supabase — Database | B9: Supabase | C9: Free / Pro | D9: 0 – 2,100/mo | E9: $0–$25/mo | F9: Monthly | G9: Included in SaaS fee | H9: Free: 500MB DB, 1GB storage, 2GB bandwidth
A10: Supabase — Auth | B10: Supabase | C10: Included in plan | D10: 0 | E10: $0 | F10: Included | G10: N/A | H10: 50,000 MAU free on Free plan
A11: Supabase — Storage | B11: Supabase | C11: Free: 1GB / Pro: 100GB | D11: 0 – 2,100/mo | E11: $0–$25/mo | F11: Monthly | G11: Included in SaaS fee | H11: Product images stored here. Pro if 1GB exceeded
A12: Email Service (Transactional) | B12: Resend / Brevo | C12: Free tier | D12: 0 – 850/mo | E12: $0–$10/mo | F12: Monthly | G12: Included in SaaS fee | H12: 3,000 emails/mo free on Resend
A13: Razorpay Setup | B13: Razorpay | C13: Free account | D13: 0 | E13: $0 | F13: One-time | G13: N/A | H13: 2% per transaction. Client pays this, not you
A14: SMS OTP (optional) | B14: Twilio / MSG91 | C14: Pay-per-use | D14: ~₹0.15–0.30 / SMS | E14: ~$0.004 | F14: Per use | G14: Pass-through to client | H14: Only needed if OTP login enabled
A15: CDN (Images) | B15: Vercel Edge / Supabase | C15: Free tier | D15: 0 | E15: $0 | F15: Included | G15: N/A | H15: Both include CDN by default
A16: Custom Email (domain mail) | B16: Zoho Mail Free / Google Workspace | C16: Free / ₹125/user/mo | D16: 0 – 125/mo | E16: $0–$1.5 | F16: Monthly | G16: Yes — upsell to client | H16: Zoho free up to 5 users. Great upsell item
A18: 📅 MONTHLY RUNNING COST — Per Active Client Store
A19: Service | B19: Provider | C19: Free Plan Limit | D19: Free Plan Cost | E19: Paid Plan | F19: Paid Plan Cost (₹) | G19: When to Upgrade | H19: Your Action
A20: Vercel Hosting | B20: Vercel | C20: 100GB bandwidth, 6000 min build | D20: ₹0 / mo | E20: Pro | F20: ₹1,700/mo | G20: When >100GB or team needed | H20: Use 1 Vercel Pro for ALL clients = ₹1,700/mo shared
A21: Supabase Database | B21: Supabase | C21: 500MB DB, 2GB bandwidth | D21: ₹0 / mo | E21: Pro | F21: ₹2,100/mo | G21: When >500MB DB or >5GB bandwidth | H21: 1 Supabase Pro org, separate projects per client
A22: Supabase Storage | B22: Supabase | C22: 1GB file storage | D22: ₹0 / mo | E22: Included in Pro | F22: Included | G22: When client has >1GB product images | H22: Upgrade project to Pro if image-heavy store
A23: Supabase Auth | B23: Supabase | C23: 50,000 MAU | D23: ₹0 / mo | E23: Included in Pro | F23: Included | G23: When >50K monthly active users | H23: Will not hit this limit for 99% clients
A24: Supabase Realtime | B24: Supabase | C24: 200 concurrent connections | D24: ₹0 / mo | E24: Included in Pro | F24: Included | G24: Large stores with live inventory | H24: Rarely needed at SMB level
A25: Vercel KV / Edge Config | B25: Vercel | C25: Included in Hobby | D25: ₹0 / mo | E25: Included in Pro | F25: Included | G25: For caching, rate limiting | H25: Optional — good for performance
A26: Email (Transactional) | B26: Resend | C26: 3,000 emails/mo | D26: ₹0 / mo | E26: Starter | F26: ₹700/mo | G26: When orders exceed ~100/day | H26: 1 Resend account for all clients (different domains)
A27: Monitoring (optional) | B27: Sentry | C27: 5,000 errors/mo | D27: ₹0 / mo | E27: Team | F27: ₹1,900/mo | G27: Production bugs start affecting clients | H27: Add to Pro package clients only
A29: 🧮 COST SCALING MODEL — Your Real Monthly Infra Expense vs Revenue
A30: Cost Item | B30: 1 Client | C30: 5 Clients | D30: 10 Clients | E30: 20 Clients | F30: 50 Clients | G30: Notes | H30: Strategy
A31: Vercel (1 Pro account) | B31: ₹0 | C31: ₹1,700 | D31: ₹1,700 | E31: ₹1,700 | F31: ₹1,700 × 2 | G31: 1 Pro handles ~30–40 stores. Add 2nd Pro at 40+ | H31: Share 1 Pro across all clients — do NOT create per client
A32: Supabase (per project) | B32: ₹0 | C32: ₹0–2,100 | D32: ₹2,100 | E32: ₹2,100 × 2 | F32: ₹2,100 × 4 | G32: Free = 500MB per project. Pro = per org (all projects) | H32: Use 1 Supabase org Pro for up to ~15–20 active clients
A33: Domain (client pays) | B33: ₹900 | C33: ₹4,500 | D33: ₹9,000 | E33: ₹18,000 | F33: ₹45,000 | G33: Pass-through + ₹500 margin each | H33: Charge client ₹1,200–1,500. You pay ₹700–1,000
A34: Email (Resend) | B34: ₹0 | C34: ₹0 | D34: ₹700 | E34: ₹700 | F34: ₹1,400 | G34: 3K emails/mo free. 1 account covers ~5–7 small stores | H34: Upgrade to Starter ₹700/mo when order volume grows
A35: Monitoring (Sentry) | B35: ₹0 | C35: ₹0 | D35: ₹0 | E35: ₹1,900 | F35: ₹1,900 | G35: Only needed for Pro/Enterprise clients | H35: Add to Pro package only — charge ₹500/mo in SaaS fee
A36: TOTAL INFRA COST/mo (₹) | B36: 0 | C36: 1700 | D36: 4500 | E36: 8400 | F36: 14800 | H36: Your cost — very low vs revenue
A37: Your SaaS Revenue/mo (₹) | B37: 2000 | C37: 10000 | D37: 25000 | E37: 60000 | F37: 175000 | G37: Avg ₹2,000/client/mo | H37: Scales much faster than cost
A38: GROSS MARGIN (₹) | B38: =C37-C36 -> 8300 | C38: =D37-D36 -> 20500 | D38: =E37-E36 -> 51600 | E38: =F37-F36 -> 160200 | F38: =F37-F36 -> 160200 | H38: This is your profit before your salary/time
A40: ✅ RECOMMENDED SETUP — Start Free, Scale Smart
A41: Phase | B41: Clients | C41: Vercel | D41: Supabase | E41: Email | F41: Domain | G41: Monthly Infra Cost | H41: Recommendation
A42: 🚀 Launch | B42: 1–3 | C42: Hobby (Free) | D42: Free tier per project | E42: Resend Free | F42: Client pays | G42: ₹0/mo | H42: Use all free tiers. Zero infra cost to start.
A43: 📈 Growing | B43: 4–10 | C43: Pro ₹1,700/mo | D43: Free/Pro ₹2,100/mo | E43: Resend Free | F43: Client pays | G43: ₹1,700–3,800/mo | H43: Upgrade Vercel Pro. Share 1 Supabase Pro org.
A44: 🏢 Scaling | B44: 11–30 | C44: Pro ₹1,700/mo | D44: 1–2 Pro Orgs | E44: Resend Starter | F44: Client pays | G44: ₹4,500–6,000/mo | H44: 1 Vercel + 2 Supabase orgs. Very manageable.
...

Sheet Outreach Scripts
A1: COLD OUTREACH SCRIPTS — Instagram DM · WhatsApp · Email · Follow-Up · Closing
A2: All leads in tracker are NOT CONTACTED yet — use these scripts to start outreach today
A3: Script Type | B3: Target | C3: Channel | D3: Hinglish Version | E3: English Version | F3: Tips
A4: Cold IG DM (No Website) | B4: IG sellers with no website link in bio | C4: Instagram | D4: Hii [Name] 👋 Aapka store dekha — bahut achha products hai! Par ek baat notice ki: aapki koi website nahi hai. Iska matlab har roz bohot saare customers aapko Google par search karte hain aur khali haath waapis jaate hain. Hum Gujarat ke small businesses ke liye professional ecommerce websites banate hain — sirf ₹15,000 se. Kya main aapko 10 minute mein ek free demo dikha sakta hoon? 🙏 | E4: Hi [Name] 👋 Loved checking out your store — great products! One thing I noticed: you don't have a website yet. That means customers searching for you on Google are finding nothing and moving on. We build professional ecommerce websites for Gujarat businesses starting at just ₹15,000. Can I show you a quick free demo? Only takes 10 minutes 🙏 | F4: • Mention 1 specific product you liked • Send 10am–12pm or 7pm–9pm • Check if they have 'link in bio' first • Follow up once after 3 days if no reply
A5: Cold WhatsApp | B5: Business owners in WhatsApp groups | C5: WhatsApp | D5: Hii [Name] 😊 Main [Your Name] hoon — hum local businesses ke liye ecommerce websites banate hain. Mainne recently [Similar City] mein ek [similar niche] store ke liye website banayi — unhe pehle 2 hafte mein 50+ orders aaye. Aapka bhi ek proper online store hona chahiye na? Main ek free demo video bhej sakta hoon — sirf 2 minute ka hai. Batao? 😊 | E5: Hi [Name] 😊 I'm [Your Name] — we build ecommerce websites for local Gujarat businesses. I recently built a store for a [similar niche] shop in [nearby city] — they received 50+ orders in their first 2 weeks. Your business deserves the same! I can send you a quick 2-min demo video for free. Interested? 😊 | F5: • Always name-drop a similar niche business • Send short message first, demo link in next msg • Best time: 8–10am or 6–8pm • Max 2 follow-ups — then move on
A6: Cold Email | B6: JustDial / IndiaMart listed businesses | C6: Email | D6: Subject: [Business Name] ke liye ek online store? Namaste [Name Bhai/Ben], Mainne aapka [Business Name] JustDial par dekha. Aapka offline business clearly strong hai! Par ek cheez miss ho rahi hai — aapki apni ecommerce website nahi hai. Iska matlab aap Amazon/Meesho ko 20–30% commission de rahe ho jo aapki hi pocket mein aa sakta tha. Hum aapke liye ek custom ecommerce website banate hain: ✅ Mobile-friendly ✅ UPI + COD payments ✅ Order management ✅ Starting ₹15,000 only Kya is hafte 15 minute ki free call ho sakti hai? Regards, [Your Name] | [Phone] | E6: Subject: Ready to take [Business Name] online? Dear [Name], I found [Business Name] on JustDial — clearly a well-established business! However, I noticed you don't have your own ecommerce website. That means you're either missing online customers or paying 20–30% commission to platforms like Amazon/Meesho. We build custom ecommerce websites for Gujarat businesses: ✅ Mobile-first design ✅ UPI + COD + Razorpay ✅ Full order management ✅ Starting at just ₹15,000 Would you be open to a free 15-minute call this week? Best, [Your Name] | [Phone] | [Website] | F6: • Business name in subject = 40% higher open rate • Send Tue–Thu, 10–11am • Include 1 portfolio link • Follow up after 3 days with a different angle
A7: Follow-Up (No Reply, Day 3) | B7: Any unresponsive lead | C7: Any Channel | D7: Hii [Name] 😊 Bas ek baar check karna tha — kya aapne mera message dekha? Main jaanta hoon aap busy rehte ho. Sirf batana chahta tha ki hum is month [City] mein sirf 3 naye clients le rahe hain. Agar interested ho toh abhi bata dena — warna koi tension nahi! 🙏 | E7: Hi [Name] 😊 Just checking in — did you get a chance to see my last message? Totally understand if things are busy! Just wanted to mention we're only taking on 3 new clients this month in [City]. Let me know if you'd like to chat — no pressure at all 🙏 | F7: • Never say 'following up' — sounds pushy • Create mild scarcity (3 slots/month) • Max 2 follow-ups per lead total • After 2nd no-reply — move to next lead
A8: Discovery Call Opener | B8: Agreed-to-call leads | C8: Phone / Video | D8: Namaste [Name], time dene ke liye shukriya! Main sirf 3 quick cheezein samajhna chahta hoon: 1. Abhi aap orders kaise manage karte ho — WhatsApp, phone, ya kuch aur? 2. Online jaane mein sabse bada concern kya hai? 3. Agar sab theek lage toh website kab tak chahiye hogi? Baaki main aapko sab guide karunga — tension mat lo! | E8: Hi [Name], thank you so much for your time! I just have 3 quick questions before I share anything: 1. How are you currently managing orders — WhatsApp, phone, or something else? 2. What's your biggest concern about going online? 3. If everything looks right, when would you ideally want to launch? Based on your answers I'll suggest exactly what fits you best! | F8: • Listen 70% — talk 30% • Never pitch in first 5 minutes • Take notes on their answers • End with: 'I'll send you a proposal by tomorrow' • Send proposal within 24 hours
A9: Closing Message (Post Demo) | B9: Leads who saw demo | C9: WhatsApp / Email | D9: Hi [Name] 😊 Demo kaisi lagi? Aapke liye maine ek quick summary banayi: ✅ Package: [Package Name] ✅ Investment: ₹[X] setup + ₹[Y]/mo ✅ Timeline: [X] days mein live ✅ Includes: [Top 3 features] Agar aaj confirm karo toh hum [Specific Date] tak launch kar sakte hain 🚀 Koi bhi sawaal ho toh batao — main yahan hoon! 🙏 | E9: Hi [Name] 😊 Hope the demo was helpful! Here's a quick summary for you: ✅ Package: [Package Name] ✅ Investment: ₹[X] setup + ₹[Y]/month ✅ Go-live: [X] working days ✅ Includes: [Top 3 features] If you confirm today, we can launch by [Specific Date] 🚀 Feel free to ask anything — happy to help! 🙏 | F9: • Always give a specific launch date • Offer 1 small bonus for fast confirmation • List only top 3 features — not everything • Follow up once after 48 hrs if no reply • Never discount more than 10%

Sheet Pipeline Dashboard
A1: SALES PIPELINE DASHBOARD — Live Summary (Auto from Lead Tracker)
A3: 📊 PIPELINE OVERVIEW
A4: Total Leads | B4: Not Contacted | C4: In Progress | D4: Interested / Demo | E4: Closed Won | F4: Closed Lost | G4: Conversion Rate | H4: Pipeline Value (₹)
A5: =COUNTA('Lead Tracker'!B4:B253) -> 250 | B5: =COUNTIF('Lead Tracker'!K4:K253,"Not Contacted") -> 250 | C5: =COUNTIF('Lead Tracker'!K4:K253,"DM Sent")+COUNTIF('Lead Tracker'!K4:K253,"Email Sent")+COUNTIF('Lead Tracker'!K4:K253,"WhatsApp Sent")+COUNTIF('Lead Tracker'!K4:K253,"Call Done") -> 0 | D5: =COUNTIF('Lead Tracker'!K4:K253,"Interested")+COUNTIF('Lead Tracker'!K4:K253,"Demo Shown")+COUNTIF('Lead Tracker'!K4:K253,"Proposal Sent") -> 0 | E5: =COUNTIF('Lead Tracker'!K4:K253,"Closed Won") -> 0 | F5: =COUNTIF('Lead Tracker'!K4:K253,"Closed Lost")+COUNTIF('Lead Tracker'!K4:K253,"Not Interested") -> 0 | G5: =IFERROR(COUNTIF('Lead Tracker'!K4:K253,"Closed Won")/COUNTA('Lead Tracker'!B4:B253),0) -> 0 | H5: =COUNTIF('Lead Tracker'!K4:K253,"Interested")*35000+COUNTIF('Lead Tracker'!K4:K253,"Proposal Sent")*40000+COUNTIF('Lead Tracker'!K4:K253,"Negotiating")*45000 -> 0
A7: 🔽 STAGE FUNNEL — Count per Status
A8: Stage | B8: Count | C8: % of Total | D8: Avg Deal (₹) | E8: Est. Pipeline (₹) | F8: Priority Action | G8: Days in Stage | H8: Next Step
A9: Not Contacted | B9: =COUNTIF('Lead Tracker'!K4:K253,"Not Contacted") -> 250 | C9: =B9/B16 -> 1 | D9: 25000 | E9: =B9*C9 -> 250 | F9: Start outreach immediately | G9: 0 | H9: Send DM/Email today
A10: DM / Email / WA Sent | B10: =COUNTIF('Lead Tracker'!K4:K253,"DM Sent")+COUNTIF('Lead Tracker'!K4:K253,"Email Sent")+COUNTIF('Lead Tracker'!K4:K253,"WhatsApp Sent") -> 0 | C10: =B10/B16 -> 0 | D10: 28000 | E10: =B10*C10 -> 0 | F10: Follow up after 3 days | G10: 1–3 days | H10: Send follow-up message
A11: Call Done | B11: =COUNTIF('Lead Tracker'!K4:K253,"Call Done") -> 0 | C11: =B11/B16 -> 0 | D11: 32000 | E11: =B11*C11 -> 0 | F11: Send proposal within 24hrs | G11: <1 day | H11: Send demo + proposal
A12: Interested / Demo Shown | B12: =COUNTIF('Lead Tracker'!K4:K253,"Interested")+COUNTIF('Lead Tracker'!K4:K253,"Demo Shown") -> 0 | C12: =B12/B16 -> 0 | D12: 38000 | E12: =B12*C12 -> 0 | F12: Schedule follow-up call | G12: 2–5 days | H12: Close with proposal
A13: Proposal Sent | B13: =COUNTIF('Lead Tracker'!K4:K253,"Proposal Sent") -> 0 | C13: =B13/B16 -> 0 | D13: 42000 | E13: =B13*C13 -> 0 | F13: Follow up after 48 hrs | G13: 2–3 days | H13: Push to confirm
A14: Negotiating | B14: =COUNTIF('Lead Tracker'!K4:K253,"Negotiating") -> 0 | C14: =B14/B16 -> 0 | D14: 45000 | E14: =B14*C14 -> 0 | F14: Offer bonus to close fast | G14: 1–2 days | H14: Close today
A15: Closed Won | B15: =COUNTIF('Lead Tracker'!K4:K253,"Closed Won") -> 0 | C15: =B15/B16 -> 0 | D15: 40000 | E15: =SUMIF('Lead Tracker'!K4:K253,"Closed Won",'Lead Tracker'!N4:N253) -> 0 | F15: Onboard & start building | G15: — | H15: Kick off project
A16: TOTAL | B16: =SUM(B9:B15) -> 250 | E16: =SUM(E9:E15) -> 250 | H16: Review every Monday
A18: 📅 WEEKLY OUTREACH CHECKLIST
A19: Monday | B19: Review all leads. Send 15 fresh DMs/emails to 'Not Contacted' leads. Update tracker.
A20: Tuesday | B20: Follow up with anyone who received a DM/email 3 days ago. Send demo video to warm leads.
A21: Wednesday | B21: Schedule calls with all 'Interested' leads. Prepare personalized proposals.
A22: Thursday | B22: Send proposals to post-call leads. Push 'Proposal Sent' leads for confirmation.
A23: Friday | B23: Close any 'Negotiating' deals. Offer small bonus (free domain, 1 extra page).
A24: Saturday | B24: Research 20 new leads on IG/JustDial. Add to tracker with 'Not Contacted' status.
A25: Sunday | B25: Review pipeline numbers. Plan next week's outreach. Update revenue projector.
